public class ExceptionExample6 {
	public static void main(String[] args) {
		int[] scores = new int[5];
		int a = 4;
		int b = (int)(Math.random() * 10);
		System.out.println("b=" + b);
		try {
			int c = a / b;
			System.out.println("cの値は" + c);
			scores[b] = 10;
			System.out.println("処理が正常に行われました");
		} 
		catch (ArithmeticException e) {
			System.out.println("ArithmeticException型の例外をキャッチしました");
			System.out.println(e);
		}
		catch (ArrayIndexOutOfBoundsException e) {
			System.out.println("ArrayIndexOutOfBoundsException型の例外をキャッチしました");
			System.out.println(e);
		}
		System.out.println("プログラムを終了します");
	}
}
